<robot
  name="selbie">
  <link
    name="base_link">
    <inertial>
      <origin
        xyz="0.14214 0.1369 0.15867"
        rpy="1.57 0 0" />
      <mass
        value="1.0483" />
      <inertia
        ixx="0.022239"
        ixy="4.5674E-09"
        ixz="-5.291E-05"
        iyy="0.0084815"
        iyz="4.6465E-06"
        izz="0.014724" />
    </inertial>
    <visual>
      <origin
        xyz="0 0 0"
        rpy="1.57 0 0" />
      <geometry>
        <mesh
          filename="package://selbie/meshes/base_link.STL" />
      </geometry>
      <material
        name="">
        <color
          rgba="0.925 0.917 0.917 1" />
      </material>
    </visual>
    <collision>
      <origin
        xyz="0 0 0"
        rpy="1.57 0 0" />
      <geometry>
        <mesh
          filename="package://selbie/meshes/base_link.STL" />
      </geometry>
    </collision>
  </link>
  <link
    name="rightWheel">
    <inertial>
      <origin
        xyz="8.582E-12 4.0312E-12 -0.017408"
        rpy="0 1.57 0" />
      <mass
        value="0.043417" />
      <inertia
        ixx="1.8225E-05"
        ixy="4.3753E-15"
        ixz="5.3517E-15"
        iyy="1.8225E-05"
        iyz="2.3697E-15"
        izz="3.4618E-05" />
    </inertial>
    <visual>
      <origin
        xyz="0 0 0"
        rpy="0 1.57 0" />
      <geometry>
        <mesh
          filename="package://selbie/meshes/rightWheel.STL" />
      </geometry>
      <material
        name="">
        <color
          rgba="0 0 0 1" />
      </material>
    </visual>
    <collision>
      <origin
        xyz="0 0 0"
        rpy="0 1.57 0" />
      <geometry>
        <mesh
          filename="package://selbie/meshes/rightWheel.STL" />
      </geometry>
    </collision>
  </link>
  <joint
    name="rj"
    type="continuous">
    <origin
      xyz="0.14286 0.097857 0.023601"
      rpy="-3.1416 -5.7356E-17 -1.9285" />
    <parent
      link="base_link" />
    <child
      link="rightWheel" />
    <axis
      xyz="0 0 -1" />
  </joint>
  <link
    name="leftWheel">
    <inertial>
      <origin
        xyz="8.582E-12 4.0312E-12 -0.017408"
        rpy="0 0 1.57" />
      <mass
        value="0.043417" />
      <inertia
        ixx="1.8225E-05"
        ixy="4.3753E-15"
        ixz="5.3517E-15"
        iyy="1.8225E-05"
        iyz="2.3697E-15"
        izz="3.4618E-05" />
    </inertial>
    <visual>
      <origin
        xyz="0 0 0"
        rpy="0 0 1.57" />
      <geometry>
        <mesh
          filename="package://selbie/meshes/leftWheel.STL" />
      </geometry>
      <material
        name="">
        <color
          rgba="0 0 0 1" />
      </material>
    </visual>
    <collision>
      <origin
        xyz="0 0 0"
        rpy="0 0 1.57" />
      <geometry>
        <mesh
          filename="package://selbie/meshes/leftWheel.STL" />
      </geometry>
    </collision>
  </link>
  <joint
    name="lj"
    type="continuous">
    <origin
      xyz="0.14286 0.097857 -0.2974"
      rpy="-6.123E-17 0 0" />
    <parent
      link="base_link" />
    <child
      link="leftWheel" />
    <axis
      xyz="0 0 1" />
  </joint>
</robot>
