<robot
  name="selbie">
  <link
    name="selbie">
    <inertial>
      <origin
        xyz="0.14214 0.1369 0.15867"
        rpy="0 0 0" />
      <mass
        value="1.0483" />
      <inertia
        ixx="0.022239"
        ixy="4.5674E-09"
        ixz="-5.291E-05"
        iyy="0.0084815"
        iyz="4.6465E-06"
        izz="0.014724" />
    </inertial>
    <visual>
      <origin
        xyz="0 0 0"
        rpy="0 0 0" />
      <geometry>
        <mesh
          filename="package://selbie/meshes/selbie.STL" />
      </geometry>
      <material
        name="">
        <color
          rgba="0.9 0.9 0.9 0.9" />
        <texture
          filename="package://selbie/textures/polished cherry.jpg" />
      </material>
    </visual>
    <collision>
      <origin
        xyz="0 0 0"
        rpy="0 0 0" />
      <geometry>
        <mesh
          filename="package://selbie/meshes/selbie.STL" />
      </geometry>
    </collision>
  </link>
  <link
    name="selbie_rightWheel">
    <inertial>
      <origin
        xyz="8.582E-12 4.0312E-12 -0.017408"
        rpy="0 0 0" />
      <mass
        value="0.043417" />
      <inertia
        ixx="1.8225E-05"
        ixy="4.3753E-15"
        ixz="5.3517E-15"
        iyy="1.8225E-05"
        iyz="2.3697E-15"
        izz="3.4618E-05" />
    </inertial>
    <visual>
      <origin
        xyz="0 0 0"
        rpy="0 0 0" />
      <geometry>
        <mesh
          filename="package://selbie/meshes/selbie_rightWheel.STL" />
      </geometry>
      <material
        name="">
        <color
          rgba="0 0 0 1" />
        <texture
          filename="package://selbie/textures/marble4.jpg" />
      </material>
    </visual>
    <collision>
      <origin
        xyz="0 0 0"
        rpy="0 0 0" />
      <geometry>
        <mesh
          filename="package://selbie/meshes/selbie_rightWheel.STL" />
      </geometry>
    </collision>
  </link>
  <joint
    name="selbie_rj"
    type="continuous">
    <origin
      xyz="0.14286 -0.023601 0.097857"
      rpy="1.5708 1.2131 3.1416" />
    <parent
      link="selbie" />
    <child
      link="selbie_rightWheel" />
    <axis
      xyz="0 0 -1" />
  </joint>
  <link
    name="selbie_leftWheel">
    <inertial>
      <origin
        xyz="8.582E-12 4.0312E-12 -0.017408"
        rpy="0 0 0" />
      <mass
        value="0.043417" />
      <inertia
        ixx="1.8225E-05"
        ixy="4.3753E-15"
        ixz="5.3517E-15"
        iyy="1.8225E-05"
        iyz="2.3697E-15"
        izz="3.4618E-05" />
    </inertial>
    <visual>
      <origin
        xyz="0 0 0"
        rpy="0 0 0" />
      <geometry>
        <mesh
          filename="package://selbie/meshes/selbie_leftWheel.STL" />
      </geometry>
      <material
        name="">
        <color
          rgba="0 0 0 1" />
        <texture
          filename="package://selbie/textures/marble4.jpg" />
      </material>
    </visual>
    <collision>
      <origin
        xyz="0 0 0"
        rpy="0 0 0" />
      <geometry>
        <mesh
          filename="package://selbie/meshes/selbie_leftWheel.STL" />
      </geometry>
    </collision>
  </link>
  <joint
    name="selbie_lj"
    type="continuous">
    <origin
      xyz="0.14286 0.2974 0.097857"
      rpy="1.5708 0 0" />
    <parent
      link="selbie" />
    <child
      link="selbie_leftWheel" />
    <axis
      xyz="0 0 1" />
  </joint>
</robot>