<?xml version="1.0" ?>
<!-- =================================================================================== -->
<!-- |    This document was autogenerated by xacro from selbie.xacro                   | -->
<!-- |    EDITING THIS FILE BY HAND IS NOT RECOMMENDED                                 | -->
<!-- =================================================================================== -->
<robot name="selbie" xmlns:xacro="http://www.ros.org/wiki/xacro">
  <!-- ros_control plugin -->
  <gazebo>
    <plugin filename="libgazebo_ros_control.so" name="gazebo_ros_control">
      <robotNamespace>/selbie</robotNamespace>
      <robotSimType>gazebo_ros_control/DefaultRobotHWSim</robotSimType>
    </plugin>
  </gazebo>
  <!-- Link1 -->
  <gazebo reference="selbie_body">
    <material>Gazebo/Blue</material>
  </gazebo>
  <!-- Link2 -->
  <gazebo reference="selbie_leftWheel">
    <mu1>0.2</mu1>
    <mu2>0.2</mu2>
    <material>Gazebo/Black</material>
  </gazebo>
  <!-- Link3 -->
  <gazebo reference="selbie_rightWheel">
    <mu1>0.2</mu1>
    <mu2>0.2</mu2>
    <material>Gazebo/Black</material>
  </gazebo>
  <material name="black">
    <color rgba="0.0 0.0 0.0 1.0"/>
  </material>
  <material name="blue">
    <color rgba="0.0 0.0 0.8 1.0"/>
  </material>
  <material name="green">
    <color rgba="0.0 0.8 0.0 1.0"/>
  </material>
  <material name="grey">
    <color rgba="0.2 0.2 0.2 1.0"/>
  </material>
  <material name="orange">
    <color rgba="1.0 0.423529411765 0.0392156862745 1.0"/>
  </material>
  <material name="brown">
    <color rgba="0.870588235294 0.811764705882 0.764705882353 1.0"/>
  </material>
  <material name="red">
    <color rgba="0.8 0.0 0.0 1.0"/>
  </material>
  <material name="white">
    <color rgba="1.0 1.0 1.0 1.0"/>
  </material>
  <link name="selbie_body">
    <inertial>
      <origin rpy="0 0 0" xyz="0.14214 0.1369 0.15867"/>
      <mass value="1.0483"/>
      <inertia ixx="0.022239" ixy="4.5674E-09" ixz="-5.291E-05" iyy="0.0084815" iyz="4.6465E-06" izz="0.014724"/>
    </inertial>
    <visual>
      <origin rpy="0 0 0" xyz="0 0 0"/>
      <geometry>
        <mesh filename="package://selbie/meshes/selbie.STL"/>
      </geometry>
      <material name="brown">
        <texture filename="package://selbie/textures/polished cherry.jpg"/>
      </material>
    </visual>
    <collision>
      <origin rpy="0 0 0" xyz="0 0 0"/>
      <geometry>
        <mesh filename="package://selbie/meshes/selbie.STL"/>
      </geometry>
    </collision>
  </link>
  <link name="selbie_rightWheel">
    <inertial>
      <origin rpy="0 0 0" xyz="8.582E-12 4.0312E-12 -0.017408"/>
      <mass value="0.043417"/>
      <inertia ixx="1.8225E-05" ixy="4.3753E-15" ixz="5.3517E-15" iyy="1.8225E-05" iyz="2.3697E-15" izz="3.4618E-05"/>
    </inertial>
    <visual>
      <origin rpy="0 0 0" xyz="0 0 0"/>
      <geometry>
        <mesh filename="package://selbie/meshes/selbie_rightWheel.STL"/>
      </geometry>
      <material name="black">
        <texture filename="package://selbie/textures/marble4.jpg"/>
      </material>
    </visual>
    <collision>
      <origin rpy="0 0 0" xyz="0 0 0"/>
      <geometry>
        <mesh filename="package://selbie/meshes/selbie_rightWheel.STL"/>
      </geometry>
    </collision>
  </link>
  <joint name="selbie_rj" type="continuous">
    <origin rpy="1.5708 1.2131 3.1416" xyz="0.14286 -0.023601 0.097857"/>
    <parent link="selbie_body"/>
    <child link="selbie_rightWheel"/>
    <axis xyz="0 0 -1"/>
  </joint>
  <link name="selbie_leftWheel">
    <inertial>
      <origin rpy="0 0 0" xyz="8.582E-12 4.0312E-12 -0.017408"/>
      <mass value="0.043417"/>
      <inertia ixx="1.8225E-05" ixy="4.3753E-15" ixz="5.3517E-15" iyy="1.8225E-05" iyz="2.3697E-15" izz="3.4618E-05"/>
    </inertial>
    <visual>
      <origin rpy="0 0 0" xyz="0 0 0"/>
      <geometry>
        <mesh filename="package://selbie/meshes/selbie_leftWheel.STL"/>
      </geometry>
      <material name="black">
        <texture filename="package://selbie/textures/marble4.jpg"/>
      </material>
    </visual>
    <collision>
      <origin rpy="0 0 0" xyz="0 0 0"/>
      <geometry>
        <mesh filename="package://selbie/meshes/selbie_leftWheel.STL"/>
      </geometry>
    </collision>
  </link>
  <joint name="selbie_lj" type="continuous">
    <origin rpy="1.5708 0 0" xyz="0.14286 0.2974 0.097857"/>
    <parent link="selbie_body"/>
    <child link="selbie_leftWheel"/>
    <axis xyz="0 0 1"/>
  </joint>
  <transmission name="tran1">
    <type>transmission_interface/SimpleTransmission</type>
    <joint name="selbie_rj">
      <hardwareInterface>EffortJointInterface</hardwareInterface>
    </joint>
    <actuator name="motor1">
      <hardwareInterface>EffortJointInterface</hardwareInterface>
      <mechanicalReduction>1</mechanicalReduction>
    </actuator>
  </transmission>
  <transmission name="tran2">
    <type>transmission_interface/SimpleTransmission</type>
    <joint name="selbie_lj">
      <hardwareInterface>EffortJointInterface</hardwareInterface>
    </joint>
    <actuator name="motor2">
      <hardwareInterface>EffortJointInterface</hardwareInterface>
      <mechanicalReduction>1</mechanicalReduction>
    </actuator>
  </transmission>
</robot>

