<?xml version="1.0"?>	
<robot
  name="selbie" xmlns:xacro="http://www.ros.org/wiki/xacro">

  <xacro:include filename="$(find selbie)/robots/selbie.gazebo" />
  <!-- Import Rviz colors -->
  <xacro:include filename="$(find selbie)/robots/materials.xacro" />
  
  <xacro:property name="camera_link" value="0.01" />

  <link name="dummy" />
  <joint name="dummy_joint" type="fixed">
	<origin xyz="0 0 -0.038"/>
	<parent link="dummy" />
	<child  link="selbie_body" />
  </joint>

  <link
    name="selbie_body">
    <inertial>
      <origin
        xyz="0.14214 0.1369 0.15867"
        rpy="0 0 0" />
      <mass
        value="1.0483" />
      <inertia
        ixx="0.022239"
        ixy="4.5674E-09"
        ixz="-5.291E-05"
        iyy="0.0084815"
        iyz="4.6465E-06"
        izz="0.014724" />
    </inertial>
    <visual>
      <origin
        xyz="0 0 0"
        rpy="0 0 0" />
      <geometry>
        <mesh
          filename="package://selbie/meshes/selbie.STL" />
      </geometry>
      <material
        name="brown">
        <texture
          filename="package://selbie/textures/polished cherry.jpg" />
      </material>
    </visual>
    <collision>
      <origin
        xyz="0 0 0"
        rpy="0 0 0" />
      <geometry>
        <mesh
          filename="package://selbie/meshes/selbie.STL" />
      </geometry>
      <surface>
          <friction>
            <ode>
              <mu>100</mu>
              <mu2>50</mu2>
            </ode>
          </friction>
	  <bounce>
              <restitution_coefficient>0</restitution_coefficient>
              <threshold>5</threshold>
            </bounce>
	   <contact>
              <ode>
                <max_vel>0</max_vel>
              </ode>
            </contact>
        </surface>
    </collision>
  </link>

<!--IMU : joint , link , sensor  -->
 <joint name="IMU_joint" type="fixed">
    <axis xyz="0 1 0"/>       
    <origin xyz="0.135 0.135 0.365" rpy="0 0 0"/>
    <parent link="selbie_body"/>
    <child link="IMU_link"/>
  </joint>

<link name="IMU_link">
  <inertial>
    <mass value="0.001"/>
    <origin rpy="0 0 0" xyz="0 0 0"/>
    <inertia ixx="0.0001" ixy="0" ixz="0" iyy="0.000001" iyz="0" izz="0.0001"/>
  </inertial>
  <visual>
    <origin rpy="0 0 0" xyz="0 0 0"/>
    <geometry>
      <box size="0.01 0.01 0.01"/>
    </geometry>
    <material name="red"/>  
  </visual>
  <collision>
    <origin rpy="0 0 0" xyz="0 0 0"/>
    <geometry>
      <box size=".01 .01 .01"/>
    </geometry>
  </collision>
</link>


<!-- Camera Link -->

  <joint name="camera_joint" type="fixed">
    <axis xyz="0 1 0" />
    <origin xyz="0.135 0.12 0.365" rpy="0 0 0"/>
    <parent link="selbie_body"/>
    <child link="camera_link"/>
  </joint>

  <!-- Camera -->
  <link name="camera_link">
    <collision>
      <origin xyz="0 0 0" rpy="0 0 0"/>
      <geometry>
    <box size="${camera_link} ${camera_link} ${camera_link}"/>
      </geometry>
    </collision>

    <visual>
      <origin xyz="0 0 0" rpy="0 0 0"/>
      <geometry>
    <box size="${camera_link} ${camera_link} ${camera_link}"/>
      </geometry>
      <material name="red"/>
    </visual>

    <inertial>
      <mass value="1e-5" />
      <origin xyz="0 0 0" rpy="0 0 0"/>
      <inertia ixx="1e-6" ixy="0" ixz="0" iyy="1e-6" iyz="0" izz="1e-6" />
    </inertial>
  </link>

<!-- Right Wheel -->
  <link
    name="selbie_rightWheel">
    <inertial>
      <origin
        xyz="8.582E-12 4.0312E-12 -0.017408"
        rpy="0 0 0" />
      <mass
        value="0.043417" />
      <inertia
        ixx="1.8225E-05"
        ixy="4.3753E-15"
        ixz="5.3517E-15"
        iyy="1.8225E-05"
        iyz="2.3697E-15"
        izz="3.4618E-05" />
    </inertial>
    <visual>
      <origin
        xyz="0 0 0"
        rpy="0 0 0" />
      <geometry>
        <mesh
          filename="package://selbie/meshes/selbie_rightWheel.STL" />
      </geometry>
      <material
        name="black">
        <texture
          filename="package://selbie/textures/marble4.jpg" />
      </material>
    </visual>
    <collision>
      <origin
        xyz="0 0 0"
        rpy="0 0 0" />
      <geometry>
        <mesh
          filename="package://selbie/meshes/selbie_rightWheel.STL" />
      </geometry>
      <surface>
          <friction>
            <ode>
              <mu>100</mu>
              <mu2>50</mu2>
            </ode>
          </friction>
	  <bounce>
              <restitution_coefficient>0</restitution_coefficient>
              <threshold>5</threshold>
            </bounce>
	   <contact>
              <ode>
                <max_vel>0</max_vel>
              </ode>
            </contact>
        </surface>
    </collision>

  </link>



  <joint
    name="selbie_rj"
    type="continuous">
    <origin
      xyz="0.14286 -0.023601 0.097857"
      rpy="1.5708 1.2131 3.1416" />
    <parent
      link="selbie_body" />
    <child
      link="selbie_rightWheel" />
    <axis
      xyz="0 0 -1" />
  </joint>


<!-- Left Wheel -->
  <link
    name="selbie_leftWheel">
    <inertial>
      <origin
        xyz="8.582E-12 4.0312E-12 -0.017408"
        rpy="0 0 0" />
      <mass
        value="0.043417" />
      <inertia
        ixx="1.8225E-05"
        ixy="4.3753E-15"
        ixz="5.3517E-15"
        iyy="1.8225E-05"
        iyz="2.3697E-15"
        izz="3.4618E-05" />
    </inertial>
    <visual>
      <origin
        xyz="0 0 0"
        rpy="0 0 0" />
      <geometry>
        <mesh
          filename="package://selbie/meshes/selbie_leftWheel.STL" />
      </geometry>
      <material
        name="black">
        <texture
          filename="package://selbie/textures/marble4.jpg" />
      </material>
    </visual>
    <collision>
      <origin
        xyz="0 0 0"
        rpy="0 0 0" />
      <geometry>
        <mesh
          filename="package://selbie/meshes/selbie_leftWheel.STL" />
      </geometry>
      <surface>
          <friction>
            <ode>
              <mu>100</mu>
              <mu2>50</mu2>
            </ode>
          </friction>
	  <bounce>
              <restitution_coefficient>0</restitution_coefficient>
              <threshold>5</threshold>
            </bounce>
	   <contact>
              <ode>
                <max_vel>0</max_vel>
              </ode>
            </contact>
        </surface>
    </collision>
  </link>



  <joint
    name="selbie_lj"
    type="continuous">
    <origin
      xyz="0.14286 0.2974 0.097857"
      rpy="1.5708 0 0" />
    <parent
      link="selbie_body" />
    <child
      link="selbie_leftWheel" />
    <axis
      xyz="0 0 1" />
  </joint>

<!-- Transmission Tags -->
  <transmission name="tran1">
    <type>transmission_interface/SimpleTransmission</type>
    <joint name="selbie_rj">
      <hardwareInterface>EffortJointInterface</hardwareInterface>
    </joint>
    <actuator name="motor1">
      <hardwareInterface>EffortJointInterface</hardwareInterface>
      <mechanicalReduction>1</mechanicalReduction>
    </actuator>
  </transmission>
	
  <transmission name="tran2">
    <type>transmission_interface/SimpleTransmission</type>
    <joint name="selbie_lj">
      <hardwareInterface>EffortJointInterface</hardwareInterface>
    </joint>
    <actuator name="motor2">
      <hardwareInterface>EffortJointInterface</hardwareInterface>
      <mechanicalReduction>1</mechanicalReduction>
    </actuator>
  </transmission>


</robot>
