<sdf version='1.5'>
  <world name='default'>
    <light name='sun' type='directional'>
      <cast_shadows>1</cast_shadows>
      <pose>0 0 10 0 -0 0</pose>
      <diffuse>0.8 0.8 0.8 1</diffuse>
      <specular>0.2 0.2 0.2 1</specular>
      <attenuation>
        <range>1000</range>
        <constant>0.9</constant>
        <linear>0.01</linear>
        <quadratic>0.001</quadratic>
      </attenuation>
      <direction>-0.5 0.1 -0.9</direction>
    </light>
    <model name='ground_plane'>
      <static>1</static>
      <link name='link'>
        <collision name='collision'>
          <geometry>
            <plane>
              <normal>0 0 1</normal>
              <size>100 100</size>
            </plane>
          </geometry>
          <surface>
            <friction>
              <ode>
                <mu>100</mu>
                <mu2>50</mu2>
              </ode>
            </friction>
            <contact>
              <ode/>
            </contact>
            <bounce/>
          </surface>
          <max_contacts>10</max_contacts>
        </collision>
        <visual name='visual'>
          <cast_shadows>0</cast_shadows>
          <geometry>
            <plane>
              <normal>0 0 1</normal>
              <size>100 100</size>
            </plane>
          </geometry>
          <material>
            <script>
              <uri>file://media/materials/scripts/gazebo.material</uri>
              <name>Gazebo/Grey</name>
            </script>
          </material>
        </visual>
        <self_collide>0</self_collide>
        <kinematic>0</kinematic>
        <gravity>1</gravity>
      </link>
    </model>
    <physics type='ode'>
      <max_step_size>0.001</max_step_size>
      <real_time_factor>1</real_time_factor>
      <real_time_update_rate>1000</real_time_update_rate>
      <gravity>0 0 -9.8</gravity>
      <magnetic_field>5.5645e-06 2.28758e-05 -4.23884e-05</magnetic_field>
    </physics>
    <scene>
      <ambient>0.4 0.4 0.4 1</ambient>
      <background>0.7 0.7 0.7 1</background>
      <shadows>1</shadows>
    </scene>
    <spherical_coordinates>
      <surface_model>EARTH_WGS84</surface_model>
      <latitude_deg>0</latitude_deg>
      <longitude_deg>0</longitude_deg>
      <elevation>0</elevation>
      <heading_deg>0</heading_deg>
    </spherical_coordinates>
    <model name='selbie'>
      <link name='selbie'>
        <pose>0 0 0 0 -0 0</pose>
        <inertial>
          <pose>0.14214 0.1369 0.15867 0 -0 0</pose>
          <mass>1.0483</mass>
          <inertia>
            <ixx>0.022239</ixx>
            <ixy>4.5674e-09</ixy>
            <ixz>-5.291e-05</ixz>
            <iyy>0.0084815</iyy>
            <iyz>4.6465e-06</iyz>
            <izz>0.014724</izz>
          </inertia>
        </inertial>
        <collision name='selbie_collision'>
          <pose>0 0 0 0 -0 0</pose>
          <geometry>
            <mesh>
              <scale>1 1 1</scale>
              <uri>/home/suryaprakaz/Documents/ROS/Robots/src/selbie/meshes/selbie.STL</uri>
            </mesh>
          </geometry>
          <max_contacts>10</max_contacts>
          <surface>
            <contact>
              <ode/>
            </contact>
            <bounce/>
            <friction>
              <ode/>
            </friction>
          </surface>
        </collision>
        <visual name='selbie_visual'>
          <pose>0 0 0 0 -0 0</pose>
          <geometry>
            <mesh>
              <scale>1 1 1</scale>
              <uri>/home/suryaprakaz/Documents/ROS/Robots/src/selbie/meshes/selbie.STL</uri>
            </mesh>
          </geometry>
        </visual>
        <self_collide>0</self_collide>
        <kinematic>0</kinematic>
        <gravity>1</gravity>
      </link>
      <link name='selbie_leftWheel'>
        <pose>0.14286 0.2974 0.097857 1.5708 -0 0</pose>
        <inertial>
          <pose>8.582e-12 4.0312e-12 -0.017408 0 -0 0</pose>
          <mass>0.043417</mass>
          <inertia>
            <ixx>1.8225e-05</ixx>
            <ixy>4.3753e-15</ixy>
            <ixz>5.3517e-15</ixz>
            <iyy>1.8225e-05</iyy>
            <iyz>2.3697e-15</iyz>
            <izz>3.4618e-05</izz>
          </inertia>
        </inertial>
        <collision name='selbie_leftWheel_collision'>
          <pose>0 0 0 0 -0 0</pose>
          <geometry>
            <mesh>
              <scale>1 1 1</scale>
              <uri>/home/suryaprakaz/Documents/ROS/Robots/src/selbie/meshes/selbie_leftWheel.STL</uri>
            </mesh>
          </geometry>
          <max_contacts>10</max_contacts>
          <surface>
            <contact>
              <ode/>
            </contact>
            <bounce/>
            <friction>
              <ode/>
            </friction>
          </surface>
        </collision>
        <visual name='selbie_leftWheel_visual'>
          <pose>0 0 0 0 -0 0</pose>
          <geometry>
            <mesh>
              <scale>1 1 1</scale>
              <uri>/home/suryaprakaz/Documents/ROS/Robots/src/selbie/meshes/selbie_leftWheel.STL</uri>
            </mesh>
          </geometry>
        </visual>
        <self_collide>0</self_collide>
        <kinematic>0</kinematic>
        <gravity>1</gravity>
      </link>
      <joint name='selbie_lj' type='revolute'>
        <child>selbie_leftWheel</child>
        <parent>selbie</parent>
        <axis>
          <xyz>0 -1 -4e-06</xyz>
          <limit>
            <lower>-1e+16</lower>
            <upper>1e+16</upper>
          </limit>
          <dynamics>
            <spring_reference>0</spring_reference>
            <spring_stiffness>0</spring_stiffness>
          </dynamics>
          <use_parent_model_frame>1</use_parent_model_frame>
        </axis>
      </joint>
      <link name='selbie_rightWheel'>
        <pose>0.14286 -0.023601 0.097857 1.5708 1.2131 -3.14159</pose>
        <inertial>
          <pose>8.582e-12 4.0312e-12 -0.017408 0 -0 0</pose>
          <mass>0.043417</mass>
          <inertia>
            <ixx>1.8225e-05</ixx>
            <ixy>4.3753e-15</ixy>
            <ixz>5.3517e-15</ixz>
            <iyy>1.8225e-05</iyy>
            <iyz>2.3697e-15</iyz>
            <izz>3.4618e-05</izz>
          </inertia>
        </inertial>
        <collision name='selbie_rightWheel_collision'>
          <pose>0 0 0 0 -0 0</pose>
          <geometry>
            <mesh>
              <scale>1 1 1</scale>
              <uri>/home/suryaprakaz/Documents/ROS/Robots/src/selbie/meshes/selbie_rightWheel.STL</uri>
            </mesh>
          </geometry>
          <max_contacts>10</max_contacts>
          <surface>
            <contact>
              <ode/>
            </contact>
            <bounce/>
            <friction>
              <ode/>
            </friction>
          </surface>
        </collision>
        <visual name='selbie_rightWheel_visual'>
          <pose>0 0 0 0 -0 0</pose>
          <geometry>
            <mesh>
              <scale>1 1 1</scale>
              <uri>/home/suryaprakaz/Documents/ROS/Robots/src/selbie/meshes/selbie_rightWheel.STL</uri>
            </mesh>
          </geometry>
        </visual>
        <self_collide>0</self_collide>
        <kinematic>0</kinematic>
        <gravity>1</gravity>
      </link>
      <joint name='selbie_rj' type='revolute'>
        <child>selbie_rightWheel</child>
        <parent>selbie</parent>
        <axis>
          <xyz>4e-06 -1 1e-06</xyz>
          <limit>
            <lower>-1e+16</lower>
            <upper>1e+16</upper>
          </limit>
          <dynamics>
            <spring_reference>0</spring_reference>
            <spring_stiffness>0</spring_stiffness>
          </dynamics>
          <use_parent_model_frame>1</use_parent_model_frame>
        </axis>
      </joint>
      <pose>0 0 0 0 -0 0</pose>
    </model>
    <state world_name='default'>
      <sim_time>3 622000000</sim_time>
      <real_time>4 637740020</real_time>
      <wall_time>1442337126 924689532</wall_time>
      <model name='ground_plane'>
        <pose>0 0 0 0 -0 0</pose>
        <link name='link'>
          <pose>0 0 0 0 -0 0</pose>
          <velocity>0 0 0 0 -0 0</velocity>
          <acceleration>0 0 0 0 -0 0</acceleration>
          <wrench>0 0 0 0 -0 0</wrench>
        </link>
      </model>
      <model name='selbie'>
        <pose>0 0 0 0 -0 0</pose>
        <link name='selbie'>
          <pose>0 0 0 0 -0 0</pose>
          <velocity>0 0 0 0 -0 0</velocity>
          <acceleration>0.534166 -5.2992 7.8113 2.20391 0.055058 -0.022392</acceleration>
          <wrench>0.559966 -5.55515 8.18858 0 -0 0</wrench>
        </link>
        <link name='selbie_leftWheel'>
          <pose>0.14286 0.2974 0.097857 1.5708 -0.454925 -2e-06</pose>
          <velocity>0 0 0 0 -0 0</velocity>
          <acceleration>1.03632 -5.50508 25.9935 0.043594 0.00046 -0.001639</acceleration>
          <wrench>0.044994 -0.239014 1.12856 0 -0 0</wrench>
        </link>
        <link name='selbie_rightWheel'>
          <pose>0.14286 -0.023601 0.097857 -1.57079 0.967813 6e-06</pose>
          <velocity>0 0 0 0 -0 0</velocity>
          <acceleration>0.269817 -5.51196 -10.9845 0.043628 0.00046 -0.0018</acceleration>
          <wrench>0.011715 -0.239313 -0.476916 0 -0 0</wrench>
        </link>
      </model>
    </state>
    <gui fullscreen='0'>
      <camera name='user_camera'>
        <pose>0.951624 -0.569633 0.499313 0 0.238991 2.25148</pose>
        <view_controller>orbit</view_controller>
      </camera>
    </gui>
  </world>
</sdf>
